<?xml version="1.0"?>
<<<<<<< HEAD
<robot name="BellowsOrigami">
=======
<robot name="omnidirectional_platform">
>>>>>>> bb41a3fc45ac7d55fc19fb45737b16eec38a25cd

    <!-- Base link -->
    <link name="base">
        <visual>
            <geometry>
<<<<<<< HEAD
                <cylinder length="0.05" radius="0.5"/>
            </geometry>
        </visual>
        <collision>
            <geometry>
                <cylinder length="0.05" radius="0.5"/>
            </geometry>
        </collision>

        <inertial>
            <mass value="2"/>
            <inertia ixx="1.0" ixy="0.0" ixz="0.0" iyy="1.0" iyz="0.0" izz="1.0"/>
        </inertial>
    </link>

    <link name="dummyLinkX">
        <inertial>
            <mass value="0.001"/>
            <inertia ixx="0.001" ixy="0" ixz="0" iyy="0.001" iyz="0" izz="0.001"/>
        </inertial>
    </link>

    <link name="dummyLinkY">
        <inertial>
            <mass value="0.001"/>
            <inertia ixx="0.001" ixy="0" ixz="0" iyy="0.001" iyz="0" izz="0.001"/>
        </inertial>
    </link>



    <!-- Segment1 link -->
    <link name="segment1">
        <visual>
            <geometry>
                <cylinder length="0.05" radius="0.5"/>
            </geometry>
        </visual>
        <collision>
            <geometry>
                <cylinder length="0.05" radius="0.5"/>
            </geometry>
        </collision>

        <inertial>
        <mass value="2"/>
        <inertia ixx="1.0" ixy="0.0" ixz="0.0" iyy="1.0" iyz="0.0" izz="1.0"/>
        </inertial>
    </link>

  
  <joint name="bend_joint_x" type="revolute">
        <parent link="base"/>
        <child link="dummyLinkX"/>
        <axis xyz="1 0 0"/>
        <limit lower="-1.57" upper="1.57" effort="10" velocity="1"/>
  </joint>
  <joint name="bend_joint_y" type="revolute">
        <parent link="dummyLinkX"/>
        <child link="dummyLinkY"/>
        <axis xyz="0 1 0"/>
        <limit lower="-1.57" upper="1.57" effort="10" velocity="1"/>
    </joint>

  <joint name="linear_joint" type="prismatic">
    <parent link="base"/>
    <child link="segment1"/>
    <axis xyz="0 0 1"/>
    <limit lower="0" upper="0.5" effort="100" velocity="0.1"/>
    <origin xyz="0 0 0.2"/>
  </joint>

 
=======
                <cylinder length="0.1" radius="0.5"/>
            </geometry>
        </visual>
    </link>
    <!-- Actuator links -->
    <link name="actuator1">
        <visual>
            <geometry>
                <cylinder length="1.0" radius="0.05"/>
            </geometry>
        </visual>
    </link>
    <link name="actuator2">
        <visual>
            <geometry>
                <cylinder length="1.0" radius="0.05"/>
            </geometry>
        </visual>
    </link>
    <link name="actuator3">
        <visual>
            <geometry>
                <cylinder length="1.0" radius="0.05"/>
            </geometry>
        </visual>
    </link>
    <!-- Top platform link -->
    <link name="platform">
        <visual>
            <geometry>
                <cylinder length="0.1" radius="0.5"/>
            </geometry>
        </visual>
    </link>

    <!-- Joints for actuators -->
    <joint name="base_to_actuator1" type="prismatic">
        <parent link="base"/>
        <child link="actuator1"/>
        <origin xyz="0.5 0 0.1"/>
        <axis xyz="0 0 1"/>
        <limit lower="0.5" upper="1.5" effort="1000.0" velocity="0.5"/>
    </joint>
    <joint name="base_to_actuator2" type="prismatic">
        <parent link="base"/>
        <child link="actuator2"/>
        <origin xyz="-0.25 0.43 0.1"/>
        <axis xyz="0 0 1"/>
        <limit lower="0.5" upper="1.5" effort="1000.0" velocity="0.5"/>
    </joint>
    <joint name="base_to_actuator3" type="prismatic">
        <parent link="base"/>
        <child link="actuator3"/>
        <origin xyz="-0.25 -0.43 0.1"/>
        <axis xyz="0 0 1"/>
        <limit lower="0.5" upper="1.5" effort="1000.0" velocity="0.5"/>
    </joint>

    <!-- Joints to connect actuators to platform -->
    <joint name="actuator1_to_platform" type="fixed">
        <parent link="actuator1"/>
        <child link="platform"/>
        <origin xyz="0 0 1.0"/>
    </joint>
    <joint name="actuator2_to_platform" type="fixed">
        <parent link="actuator2"/>
        <child link="platform"/>
        <origin xyz="0 0 1.0"/>
    </joint>
    <joint name="actuator3_to_platform" type="fixed">
        <parent link="actuator3"/>
        <child link="platform"/>
        <origin xyz="0 0 1.0"/>
    </joint>
>>>>>>> bb41a3fc45ac7d55fc19fb45737b16eec38a25cd

</robot>
