<robot name="simple_robot">

  <!-- Link 1 -->
  <link name="link1">
    <visual>
      <geometry>
        <cylinder length="0.5" radius="0.1"/>
      </geometry>
    </visual>
    <collision>
      <geometry>
        <cylinder length="0.5" radius="0.1"/>
      </geometry>
    </collision>
    <inertial>
      <mass value="1.0"/>
      <inertia ixx="0.01" ixy="0.0" ixz="0.0" iyy="0.01" iyz="0.0" izz="0.01"/>
    </inertial>
  </link>

  <!-- Joint 1 -->
  <joint name="joint1" type="revolute">
    <parent link="link1"/>
    <child link="link2"/>
    <axis xyz="0 0 1"/>
    <limit lower="-1.57" upper="1.57" effort="10.0" velocity="1.0"/>
  </joint>

  <!-- Link 2 -->
  <link name="link2">
    <!-- Similar to link1 -->
  </link>

  <!-- Joint 2 -->
  <joint name="joint2" type="revolute">
    <parent link="link2"/>
    <child link="link3"/>
    <!-- Similar properties as joint1 -->
  </joint>

  <!-- Link 3 (if needed) -->
  <!-- ... -->

</robot>